def function(a):
    """
    traceback error:
    """
    pass

function(0, a=0)





#record:
"""
(base) zcw@mukoedo1993:~/python_related_clone/Python_related/python_official_tutorial/chap4_7$ python traceback_error.py
Traceback (most recent call last):
  File "traceback_error.py", line 4, in <module>
    function(0, a=0)
TypeError: function() got multiple values for argument 'a'
"""